<?xml version="1.0" encoding="UTF-8" standalone="no"?>
<robot name="nissan_leaf">
  <link name="base_footprint">
    <visual>
      <origin rpy="1.5707963146269321 0.0 1.5707963146269321" xyz="0.0 0.0 0.0"/>
      <geometry>
        <cylinder length="2.0" radius="0.05"/>
      </geometry>
    </visual>
    <inertial>
      <mass value="0.0"/>
      <inertia ixx="0.33395833333333336" ixy="0.0" ixz="0.0" iyy="0.33395833333333336" iyz="0.0" izz="0.0012500000000000002"/>
    </inertial>
    <collision>
      <origin rpy="1.5707963146269321 0.0 1.5707963146269321" xyz="0.0 0.0 0.0"/>
      <geometry>
        <cylinder length="2.0" radius="0.05"/>
      </geometry>
    </collision>
    <inertial>
      <mass value="0.0"/>
      <inertia ixx="0.0" ixy="0.0" ixz="0.0" iyy="0.0" iyz="0.0" izz="0.0"/>
    </inertial>
  </link>
  <link name="rear_axle_link">
    <visual>
      <origin rpy="1.5707963146269321 0.0 0.0" xyz="0.0 0.0 0.0"/>
      <geometry>
        <cylinder length="1.0" radius="0.05"/>
      </geometry>
    </visual>
    <inertial>
      <mass value="10.0"/>
      <inertia ixx="0.08395833333333334" ixy="0.0" ixz="0.0" iyy="0.08395833333333334" iyz="0.0" izz="0.0012500000000000002"/>
    </inertial>
    <collision>
      <origin rpy="1.5707963146269321 0.0 0.0" xyz="0.0 0.0 0.0"/>
      <geometry>
        <cylinder length="1.0" radius="0.05"/>
      </geometry>
    </collision>
  </link>
  <link name="front_axle_link">
    <visual>
      <origin rpy="1.5707963146269321 0.0 0.0" xyz="0.0 0.0 0.0"/>
      <geometry>
        <cylinder length="1.0" radius="0.05"/>
      </geometry>
    </visual>
    <inertial>
      <mass value="10.0"/>
      <inertia ixx="0.08395833333333334" ixy="0.0" ixz="0.0" iyy="0.08395833333333334" iyz="0.0" izz="0.0012500000000000002"/>
    </inertial>
    <collision>
      <origin rpy="1.5707963146269321 0.0 0.0" xyz="0.0 0.0 0.0"/>
      <geometry>
        <cylinder length="1.0" radius="0.05"/>
      </geometry>
    </collision>
  </link>
  <link name="front_left_wheel_link">
    <visual>
      <origin rpy="1.5707963146269321 0.0 0.0" xyz="0.0 0.0 0.0"/>
      <geometry>
        <cylinder length="0.05" radius="0.1"/>
      </geometry>
    </visual>
    <inertial>
      <mass value="2.0"/>
      <inertia ixx="0.002708333333333334" ixy="0.0" ixz="0.0" iyy="0.002708333333333334" iyz="0.0" izz="0.005000000000000001"/>
    </inertial>
    <collision>
      <origin rpy="1.5707963146269321 0.0 0.0" xyz="0.0 0.0 0.0"/>
      <geometry>
        <cylinder length="0.05" radius="0.1"/>
      </geometry>
    </collision>
  </link>
  <link name="front_right_wheel_link">
    <visual>
      <origin rpy="1.5707963146269321 0.0 0.0" xyz="0.0 0.0 0.0"/>
      <geometry>
        <cylinder length="0.05" radius="0.1"/>
      </geometry>
    </visual>
    <inertial>
      <mass value="2.0"/>
      <inertia ixx="0.002708333333333334" ixy="0.0" ixz="0.0" iyy="0.002708333333333334" iyz="0.0" izz="0.005000000000000001"/>
    </inertial>
    <collision>
      <origin rpy="1.5707963146269321 0.0 0.0" xyz="0.0 0.0 0.0"/>
      <geometry>
        <cylinder length="0.05" radius="0.1"/>
      </geometry>
    </collision>
  </link>
  <link name="rear_left_wheel_link">
    <visual>
      <origin rpy="1.5707963146269321 0.0 0.0" xyz="0.0 0.0 0.0"/>
      <geometry>
        <cylinder length="0.1" radius="0.05"/>
      </geometry>
    </visual>
    <inertial>
      <mass value="2.0"/>
      <inertia ixx="0.0014583333333333334" ixy="0.0" ixz="0.0" iyy="0.0014583333333333334" iyz="0.0" izz="0.0012500000000000002"/>
    </inertial>
    <collision>
      <origin rpy="1.5707963146269321 0.0 0.0" xyz="0.0 0.0 0.0"/>
      <geometry>
        <cylinder length="0.1" radius="0.05"/>
      </geometry>
    </collision>
  </link>
  <link name="rear_right_wheel_link">
    <visual>
      <origin rpy="1.5707963146269321 0.0 0.0" xyz="0.0 0.0 0.0"/>
      <geometry>
        <cylinder length="0.1" radius="0.05"/>
      </geometry>
    </visual>
    <inertial>
      <mass value="2.0"/>
      <inertia ixx="0.0014583333333333334" ixy="0.0" ixz="0.0" iyy="0.0014583333333333334" iyz="0.0" izz="0.0012500000000000002"/>
    </inertial>
    <collision>
      <origin rpy="1.5707963146269321 0.0 0.0" xyz="0.0 0.0 0.0"/>
      <geometry>
        <cylinder length="0.1" radius="0.05"/>
      </geometry>
    </collision>
  </link>
  <link name="front_steer_left_wheel_link">
    <visual>
      <origin xyz="0.0 0.0 0.0"/>
      <geometry>
        <cylinder length="0.1" radius="0.05"/>
      </geometry>
    </visual>
    <inertial>
      <mass value="2.0"/>
      <inertia ixx="0.0014583333333333334" ixy="0.0" ixz="0.0" iyy="0.0014583333333333334" iyz="0.0" izz="0.0012500000000000002"/>
    </inertial>
    <collision>
      <origin xyz="0.0 0.0 0.0"/>
      <geometry>
        <cylinder length="0.1" radius="0.05"/>
      </geometry>
    </collision>
  </link>
  <link name="front_steer_right_wheel_link">
    <visual>
      <origin xyz="0.0 0.0 0.0"/>
      <geometry>
        <cylinder length="0.1" radius="0.05"/>
      </geometry>
    </visual>
    <inertial>
      <mass value="2.0"/>
      <inertia ixx="0.0014583333333333334" ixy="0.0" ixz="0.0" iyy="0.0014583333333333334" iyz="0.0" izz="0.0012500000000000002"/>
    </inertial>
    <collision>
      <origin xyz="0.0 0.0 0.0"/>
      <geometry>
        <cylinder length="0.1" radius="0.05"/>
      </geometry>
    </collision>
  </link>
  <link name="front_left_wheel_link_drive">
    <visual>
      <origin rpy="1.5707963146269321 0.0 0.0" xyz="0.0 0.0 0.0"/>
      <geometry>
        <cylinder length="0.1" radius="0.27"/>
      </geometry>
    </visual>
    <inertial>
      <mass value="10.0"/>
      <inertia ixx="0.019058333333333337" ixy="0.0" ixz="0.0" iyy="0.019058333333333337" iyz="0.0" izz="0.03645"/>
    </inertial>
    <collision>
      <origin rpy="1.5707963146269321 0.0 0.0" xyz="0.0 0.0 0.0"/>
      <geometry>
        <cylinder length="0.1" radius="0.27"/>
      </geometry>
    </collision>
  </link>
  <link name="front_right_wheel_link_drive">
    <visual>
      <origin rpy="1.5707963146269321 0.0 0.0" xyz="0.0 0.0 0.0"/>
      <geometry>
        <cylinder length="0.1" radius="0.27"/>
      </geometry>
    </visual>
    <inertial>
      <mass value="10.0"/>
      <inertia ixx="0.019058333333333337" ixy="0.0" ixz="0.0" iyy="0.019058333333333337" iyz="0.0" izz="0.03645"/>
    </inertial>
    <collision>
      <origin rpy="1.5707963146269321 0.0 0.0" xyz="0.0 0.0 0.0"/>
      <geometry>
        <cylinder length="0.1" radius="0.27"/>
      </geometry>
    </collision>
  </link>
  <link name="rear_left_wheel_link_drive">
    <visual>
      <origin rpy="1.5707963146269321 0.0 0.0" xyz="0.0 0.0 0.0"/>
      <geometry>
        <cylinder length="0.1" radius="0.27"/>
      </geometry>
    </visual>
    <inertial>
      <mass value="10.0"/>
      <inertia ixx="0.019058333333333337" ixy="0.0" ixz="0.0" iyy="0.019058333333333337" iyz="0.0" izz="0.03645"/>
    </inertial>
    <collision>
      <origin rpy="1.5707963146269321 0.0 0.0" xyz="0.0 0.0 0.0"/>
      <geometry>
        <cylinder length="0.1" radius="0.27"/>
      </geometry>
    </collision>
  </link>
  <link name="rear_right_wheel_link_drive">
    <visual>
      <origin rpy="1.5707963146269321 0.0 0.0" xyz="0.0 0.0 0.0"/>
      <geometry>
        <cylinder length="0.1" radius="0.27"/>
      </geometry>
    </visual>
    <inertial>
      <mass value="10.0"/>
      <inertia ixx="0.019058333333333337" ixy="0.0" ixz="0.0" iyy="0.019058333333333337" iyz="0.0" izz="0.03645"/>
    </inertial>
    <collision>
      <origin rpy="1.5707963146269321 0.0 0.0" xyz="0.0 0.0 0.0"/>
      <geometry>
        <cylinder length="0.1" radius="0.27"/>
      </geometry>
    </collision>
  </link>
  <link name="link_laser_front">
    <visual>
      <origin xyz="0.0 0.0 0.0"/>
      <geometry>
        <sphere radius="0.1"/>
      </geometry>
    </visual>
    <inertial>
      <mass value="5.0"/>
      <inertia ixx="0.20000000596046452" ixy="0.0" ixz="0.0" iyy="0.20000000596046452" iyz="0.0" izz="0.20000000596046452"/>
    </inertial>
    <collision>
      <origin xyz="0.0 0.0 0.0"/>
      <geometry>
        <sphere radius="0.1"/>
      </geometry>
    </collision>
  </link>
  <joint name="axle_front" type="fixed">
    <parent link="base_footprint"/>
    <child link="front_axle_link"/>
    <axis xyz="1.0 0.0 0.0"/>
    <origin xyz="1.0 0.0 0.0"/>
  </joint>
  <joint name="axle_rear" type="fixed">
    <parent link="base_footprint"/>
    <child link="rear_axle_link"/>
    <axis xyz="1.0 0.0 0.0"/>
    <origin xyz="-1.0 0.0 0.0"/>
  </joint>
  <joint name="axle_front_left" type="fixed">
    <parent link="front_axle_link"/>
    <child link="front_steer_left_wheel_link"/>
    <axis xyz="0.0 1.0 0.0"/>
    <origin xyz="0.0 -0.5 0.0"/>
  </joint>
  <joint name="axle_front_right" type="fixed">
    <parent link="front_axle_link"/>
    <child link="front_steer_right_wheel_link"/>
    <axis xyz="0.0 1.0 0.0"/>
    <origin xyz="0.0 0.5 0.0"/>
  </joint>
  <joint name="axle_rear_left" type="fixed">
    <parent link="rear_axle_link"/>
    <child link="rear_left_wheel_link"/>
    <axis xyz="0.0 1.0 0.0"/>
    <origin xyz="0.0 -0.5 0.0"/>
  </joint>
  <joint name="axle_rear_right" type="fixed">
    <parent link="rear_axle_link"/>
    <child link="rear_right_wheel_link"/>
    <axis xyz="0.0 1.0 0.0"/>
    <origin xyz="0.0 0.5 0.0"/>
  </joint>
  <joint name="jnt_front_left_steer" type="revolute">
    <parent link="front_steer_left_wheel_link"/>
    <child link="front_left_wheel_link"/>
    <axis xyz="0.0 0.0 1.0"/>
    <limit effort="0.0" lower="0.4886921905584123" upper="0.5235987755982988" velocity="0.0"/>
  </joint>
  <joint name="jnt_front_right_steer" type="revolute">
    <parent link="front_steer_right_wheel_link"/>
    <child link="front_right_wheel_link"/>
    <axis xyz="0.0 0.0 1.0"/>
    <limit effort="0.0" lower="-0.5235987755982988" upper="-0.4886921905584123" velocity="0.0"/>
  </joint>
  <joint name="joint_wheel_front_left" type="continuous">
    <parent link="front_left_wheel_link"/>
    <child link="front_left_wheel_link_drive"/>
    <axis xyz="0.0 1.0 0.0"/>
  </joint>
  <joint name="joint_wheel_front_right" type="continuous">
    <parent link="front_right_wheel_link"/>
    <child link="front_right_wheel_link_drive"/>
    <axis xyz="0.0 1.0 0.0"/>
  </joint>
  <joint name="joint_wheel_rear_left" type="continuous">
    <parent link="rear_left_wheel_link"/>
    <child link="rear_left_wheel_link_drive"/>
    <axis xyz="0.0 1.0 0.0"/>
  </joint>
  <joint name="joint_wheel_rear_right" type="continuous">
    <parent link="rear_right_wheel_link"/>
    <child link="rear_right_wheel_link_drive"/>
    <axis xyz="0.0 1.0 0.0"/>
  </joint>
  <joint name="jnt_laser" type="fixed">
    <parent link="base_footprint"/>
    <child link="link_laser_front"/>
    <axis xyz="0.0 0.0 1.0"/>
    <origin xyz="1.2 0.0 0.0"/>
  </joint>
  <gazebo reference="link_laser_front">
    <sensor name="laser" type="ray">
      <update_rate>50</update_rate>
      <ray>
        <scan>
          <horizontal>
            <samples>540</samples>
            <resolution>1</resolution>
            <min_angle>-2.0943952</min_angle>
            <max_angle>2.0943952</max_angle>
          </horizontal>
        </scan>
        <range>
          <min>0.4</min>
          <max>30.0</max>
          <resolution>0.1</resolution>
        </range>
      </ray>
      <plugin filename="libgazebo_ros_laser.so" name="laser_laser">
        <topicName>laser/scan</topicName>
        <frameName>link_laser_front</frameName>
      </plugin>
    </sensor>
  </gazebo>
</robot>
