<?xml version="1.0" encoding="UTF-8" standalone="no"?>
<robot name="nissanleaf">
  <!--GEN START: Kinematic links-->
  <!--GEN LINK: base_link-->
  <link name="base_link">
    <visual>
      <origin rpy="1.5707963146269321 0.0 1.5707963146269321" xyz="0.0 0.0 0.0"/>
      <geometry>
        <cylinder length="2.7" radius="0.05"/>
      </geometry>
    </visual>
    <visual>
      <origin rpy="0.0 0.0 0.0" xyz="-2.15 0.0 -0.4"/>
      <geometry>
        <mesh filename="package://szelectricity_description/meshes/Nissan_LEAF_wo_wheels_yellow.obj" scale="1.0 1.0 1.0"/>
      </geometry>
    </visual>
    <inertial>
      <inertia ixx="385.1333333333333" ixy="0.0" ixz="0.0" iyy="795.0" iyz="0.0" izz="805.1333333333333"/>
      <mass value="0.0"/>
    </inertial>
    <collision>
      <origin rpy="1.5707963146269321 0.0 1.5707963146269321" xyz="0.0 0.0 0.0"/>
      <geometry>
        <cylinder length="2.7" radius="0.05"/>
      </geometry>
    </collision>
    <inertial>
      <inertia ixx="385.1333333333333" ixy="0.0" ixz="0.0" iyy="795.0" iyz="0.0" izz="805.1333333333333"/>
      <mass value="0.0"/>
    </inertial>
    <collision>
      <geometry>
        <mesh filename="package://szelectricity_description/meshes/Nissan_LEAF_wo_wheels_yellow.obj" scale="1.0 1.0 1.0"/>
      </geometry>
      <origin rpy="0.0 0.0 0.0" xyz="-2.15 0.0 -0.4"/>
    </collision>
    <inertial>
      <mass value="0.0"/>
      <inertia ixx="0.0" ixy="0.0" ixz="0.0" iyy="0.0" iyz="0.0" izz="0.0"/>
    </inertial>
  </link>
  <!--GEN LINK: rear_axle_link-->
  <link name="rear_axle_link">
    <visual>
      <origin rpy="1.5707963146269321 0.0 0.0" xyz="0.0 0.0 0.0"/>
      <geometry>
        <cylinder length="1.535" radius="0.05"/>
      </geometry>
    </visual>
    <inertial>
      <mass value="10.0"/>
      <inertia ixx="1.969770833333333" ixy="0.0" ixz="0.0" iyy="1.969770833333333" iyz="0.0" izz="0.012500000000000002"/>
    </inertial>
    <collision>
      <origin rpy="1.5707963146269321 0.0 0.0" xyz="0.0 0.0 0.0"/>
      <geometry>
        <cylinder length="1.535" radius="0.05"/>
      </geometry>
    </collision>
  </link>
  <!--GEN LINK: front_axle_link-->
  <link name="front_axle_link">
    <visual>
      <origin rpy="1.5707963146269321 0.0 0.0" xyz="0.0 0.0 0.0"/>
      <geometry>
        <cylinder length="1.54" radius="0.05"/>
      </geometry>
    </visual>
    <inertial>
      <mass value="10.0"/>
      <inertia ixx="1.9825833333333331" ixy="0.0" ixz="0.0" iyy="1.9825833333333331" iyz="0.0" izz="0.012500000000000002"/>
    </inertial>
    <collision>
      <origin rpy="1.5707963146269321 0.0 0.0" xyz="0.0 0.0 0.0"/>
      <geometry>
        <cylinder length="1.54" radius="0.05"/>
      </geometry>
    </collision>
  </link>
  <!--GEN LINK: front_left_wheel_link-->
  <link name="front_left_wheel_link">
    <visual>
      <origin rpy="1.5707963146269321 0.0 0.0" xyz="0.0 0.0 0.0"/>
      <geometry>
        <cylinder length="0.05" radius="0.1"/>
      </geometry>
    </visual>
    <inertial>
      <mass value="2.0"/>
      <inertia ixx="0.005416666666666668" ixy="0.0" ixz="0.0" iyy="0.005416666666666668" iyz="0.0" izz="0.010000000000000002"/>
    </inertial>
    <collision>
      <origin rpy="1.5707963146269321 0.0 0.0" xyz="0.0 0.0 0.0"/>
      <geometry>
        <cylinder length="0.05" radius="0.1"/>
      </geometry>
    </collision>
  </link>
  <!--GEN LINK: front_right_wheel_link-->
  <link name="front_right_wheel_link">
    <visual>
      <origin rpy="1.5707963146269321 0.0 0.0" xyz="0.0 0.0 0.0"/>
      <geometry>
        <cylinder length="0.05" radius="0.1"/>
      </geometry>
    </visual>
    <inertial>
      <mass value="2.0"/>
      <inertia ixx="0.005416666666666668" ixy="0.0" ixz="0.0" iyy="0.005416666666666668" iyz="0.0" izz="0.010000000000000002"/>
    </inertial>
    <collision>
      <origin rpy="1.5707963146269321 0.0 0.0" xyz="0.0 0.0 0.0"/>
      <geometry>
        <cylinder length="0.05" radius="0.1"/>
      </geometry>
    </collision>
  </link>
  <!--GEN LINK: rear_left_wheel_link-->
  <link name="rear_left_wheel_link">
    <visual>
      <origin rpy="1.5707963146269321 0.0 0.0" xyz="0.0 0.0 0.0"/>
      <geometry>
        <cylinder length="0.1" radius="0.05"/>
      </geometry>
    </visual>
    <inertial>
      <mass value="2.0"/>
      <inertia ixx="0.002916666666666667" ixy="0.0" ixz="0.0" iyy="0.002916666666666667" iyz="0.0" izz="0.0025000000000000005"/>
    </inertial>
    <collision>
      <origin rpy="1.5707963146269321 0.0 0.0" xyz="0.0 0.0 0.0"/>
      <geometry>
        <cylinder length="0.1" radius="0.05"/>
      </geometry>
    </collision>
  </link>
  <!--GEN LINK: rear_right_wheel_link-->
  <link name="rear_right_wheel_link">
    <visual>
      <origin rpy="1.5707963146269321 0.0 0.0" xyz="0.0 0.0 0.0"/>
      <geometry>
        <cylinder length="0.1" radius="0.05"/>
      </geometry>
    </visual>
    <inertial>
      <mass value="2.0"/>
      <inertia ixx="0.002916666666666667" ixy="0.0" ixz="0.0" iyy="0.002916666666666667" iyz="0.0" izz="0.0025000000000000005"/>
    </inertial>
    <collision>
      <origin rpy="1.5707963146269321 0.0 0.0" xyz="0.0 0.0 0.0"/>
      <geometry>
        <cylinder length="0.1" radius="0.05"/>
      </geometry>
    </collision>
  </link>
  <!--GEN LINK: front_steer_left_wheel_link-->
  <link name="front_steer_left_wheel_link">
    <visual>
      <origin xyz="0.0 0.0 0.0"/>
      <geometry>
        <cylinder length="0.1" radius="0.05"/>
      </geometry>
    </visual>
    <inertial>
      <mass value="2.0"/>
      <inertia ixx="0.002916666666666667" ixy="0.0" ixz="0.0" iyy="0.002916666666666667" iyz="0.0" izz="0.0025000000000000005"/>
    </inertial>
    <collision>
      <origin xyz="0.0 0.0 0.0"/>
      <geometry>
        <cylinder length="0.1" radius="0.05"/>
      </geometry>
    </collision>
  </link>
  <!--GEN LINK: front_steer_right_wheel_link-->
  <link name="front_steer_right_wheel_link">
    <visual>
      <origin xyz="0.0 0.0 0.0"/>
      <geometry>
        <cylinder length="0.1" radius="0.05"/>
      </geometry>
    </visual>
    <inertial>
      <mass value="2.0"/>
      <inertia ixx="0.002916666666666667" ixy="0.0" ixz="0.0" iyy="0.002916666666666667" iyz="0.0" izz="0.0025000000000000005"/>
    </inertial>
    <collision>
      <origin xyz="0.0 0.0 0.0"/>
      <geometry>
        <cylinder length="0.1" radius="0.05"/>
      </geometry>
    </collision>
  </link>
  <!--GEN LINK: front_left_wheel_link_drive-->
  <link name="front_left_wheel_link_drive">
    <visual>
      <origin rpy="1.5707963146269321 0.0 -1.5707963146269321" xyz="0.0 0.0 0.0"/>
      <geometry>
        <mesh filename="package://szelectricity_description/meshes/NissanKerek.DAE" scale="1.0 1.0 1.0"/>
      </geometry>
    </visual>
    <inertial>
      <inertia ixx="0.30633686558333334" ixy="0.0" ixz="0.0" iyy="0.30633686558333334" iyz="0.0" izz="0.5000070645"/>
      <mass value="10.0"/>
    </inertial>
    <collision>
      <geometry>
        <mesh filename="package://szelectricity_description/meshes/NissanKerekCollision.obj" scale="1.0 1.0 1.0"/>
      </geometry>
      <origin rpy="0.0 0.0 -1.5707963146269321" xyz="0.0 0.0 0.0"/>
    </collision>
  </link>
  <!--GEN LINK: front_right_wheel_link_drive-->
  <link name="front_right_wheel_link_drive">
    <visual>
      <origin rpy="1.5707963146269321 0.0 1.5707963146269321" xyz="0.0 0.0 0.0"/>
      <geometry>
        <mesh filename="package://szelectricity_description/meshes/NissanKerek.DAE" scale="1.0 1.0 1.0"/>
      </geometry>
    </visual>
    <inertial>
      <inertia ixx="0.30633686558333334" ixy="0.0" ixz="0.0" iyy="0.30633686558333334" iyz="0.0" izz="0.5000070645"/>
      <mass value="10.0"/>
    </inertial>
    <collision>
      <geometry>
        <mesh filename="package://szelectricity_description/meshes/NissanKerekCollision.obj" scale="1.0 1.0 1.0"/>
      </geometry>
      <origin rpy="0.0 0.0 1.5707963146269321" xyz="0.0 0.0 0.0"/>
    </collision>
  </link>
  <!--GEN LINK: rear_left_wheel_link_drive-->
  <link name="rear_left_wheel_link_drive">
    <visual>
      <origin rpy="1.5707963146269321 0.0 -1.5707963146269321" xyz="0.0 0.0 0.0"/>
      <geometry>
        <mesh filename="package://szelectricity_description/meshes/NissanKerek.DAE" scale="1.0 1.0 1.0"/>
      </geometry>
    </visual>
    <inertial>
      <inertia ixx="0.30633686558333334" ixy="0.0" ixz="0.0" iyy="0.30633686558333334" iyz="0.0" izz="0.5000070645"/>
      <mass value="10.0"/>
    </inertial>
    <collision>
      <geometry>
        <mesh filename="package://szelectricity_description/meshes/NissanKerekCollision.obj" scale="1.0 1.0 1.0"/>
      </geometry>
      <origin rpy="0.0 0.0 -1.5707963146269321" xyz="0.0 0.0 0.0"/>
    </collision>
  </link>
  <!--GEN LINK: rear_right_wheel_link_drive-->
  <link name="rear_right_wheel_link_drive">
    <visual>
      <origin rpy="1.5707963146269321 0.0 1.5707963146269321" xyz="0.0 0.0 0.0"/>
      <geometry>
        <mesh filename="package://szelectricity_description/meshes/NissanKerek.DAE" scale="1.0 1.0 1.0"/>
      </geometry>
    </visual>
    <inertial>
      <inertia ixx="0.30633686558333334" ixy="0.0" ixz="0.0" iyy="0.30633686558333334" iyz="0.0" izz="0.5000070645"/>
      <mass value="10.0"/>
    </inertial>
    <collision>
      <geometry>
        <mesh filename="package://szelectricity_description/meshes/NissanKerekCollision.obj" scale="1.0 1.0 1.0"/>
      </geometry>
      <origin rpy="0.0 0.0 1.5707963146269321" xyz="0.0 0.0 0.0"/>
    </collision>
  </link>
  <!--GEN LINK: link_gnss_kvh-->
  <link name="link_gnss_kvh">
    <visual>
      <origin xyz="0.0 0.0 0.0"/>
      <geometry>
        <sphere radius="0.1"/>
      </geometry>
    </visual>
    <inertial>
      <mass value="5.0"/>
      <inertia ixx="0.20000000596046452" ixy="0.0" ixz="0.0" iyy="0.20000000596046452" iyz="0.0" izz="0.20000000596046452"/>
    </inertial>
    <collision>
      <origin xyz="0.0 0.0 0.0"/>
      <geometry>
        <sphere radius="0.1"/>
      </geometry>
    </collision>
  </link>
  <!--GEN LINK: link_laser_front-->
  <link name="link_laser_front">
    <visual>
      <origin xyz="0.0 0.0 0.0"/>
      <geometry>
        <sphere radius="0.1"/>
      </geometry>
    </visual>
    <inertial>
      <mass value="5.0"/>
      <inertia ixx="0.20000000596046452" ixy="0.0" ixz="0.0" iyy="0.20000000596046452" iyz="0.0" izz="0.20000000596046452"/>
    </inertial>
    <collision>
      <origin xyz="0.0 0.0 0.0"/>
      <geometry>
        <sphere radius="0.1"/>
      </geometry>
    </collision>
  </link>
  <!--GEN LINK: link_vlp16-->
  <link name="link_vlp16">
    <visual>
      <origin xyz="0.0 0.0 0.0"/>
      <geometry>
        <sphere radius="0.1"/>
      </geometry>
    </visual>
    <inertial>
      <mass value="10.0"/>
      <inertia ixx="0.40000001192092904" ixy="0.0" ixz="0.0" iyy="0.40000001192092904" iyz="0.0" izz="0.40000001192092904"/>
    </inertial>
    <collision>
      <origin xyz="0.0 0.0 0.0"/>
      <geometry>
        <sphere radius="0.1"/>
      </geometry>
    </collision>
  </link>
  <!--GEN LINK: link_camera-->
  <link name="link_camera">
    <visual>
      <origin xyz="0.0 0.0 0.0"/>
      <geometry>
        <sphere radius="0.1"/>
      </geometry>
    </visual>
    <inertial>
      <mass value="10.0"/>
      <inertia ixx="0.40000001192092904" ixy="0.0" ixz="0.0" iyy="0.40000001192092904" iyz="0.0" izz="0.40000001192092904"/>
    </inertial>
    <collision>
      <origin xyz="0.0 0.0 0.0"/>
      <geometry>
        <sphere radius="0.1"/>
      </geometry>
    </collision>
  </link>
  <!--GEN LINK: link_imu_sensor-->
  <link name="link_imu_sensor">
    <visual>
      <origin xyz="0.0 0.0 0.0"/>
      <geometry>
        <sphere radius="0.1"/>
      </geometry>
    </visual>
    <inertial>
      <mass value="0.5"/>
      <inertia ixx="0.020000000596046452" ixy="0.0" ixz="0.0" iyy="0.020000000596046452" iyz="0.0" izz="0.020000000596046452"/>
    </inertial>
    <collision>
      <origin xyz="0.0 0.0 0.0"/>
      <geometry>
        <sphere radius="0.1"/>
      </geometry>
    </collision>
  </link>
  <!--GEN START: Kinematic joints-->
  <joint name="axle_front" type="fixed">
    <parent link="base_link"/>
    <child link="front_axle_link"/>
    <axis xyz="1.0 0.0 0.0"/>
    <origin xyz="1.350000023841858 0.0 0.0"/>
  </joint>
  <joint name="axle_rear" type="fixed">
    <parent link="base_link"/>
    <child link="rear_axle_link"/>
    <axis xyz="1.0 0.0 0.0"/>
    <origin xyz="-1.350000023841858 0.0 0.0"/>
  </joint>
  <joint name="axle_front_left" type="fixed">
    <parent link="front_axle_link"/>
    <child link="front_steer_left_wheel_link"/>
    <axis xyz="0.0 1.0 0.0"/>
    <origin xyz="0.0 -0.7699999809265137 0.0"/>
  </joint>
  <joint name="axle_front_right" type="fixed">
    <parent link="front_axle_link"/>
    <child link="front_steer_right_wheel_link"/>
    <axis xyz="0.0 1.0 0.0"/>
    <origin xyz="0.0 0.7699999809265137 0.0"/>
  </joint>
  <joint name="axle_rear_left" type="fixed">
    <parent link="rear_axle_link"/>
    <child link="rear_left_wheel_link"/>
    <axis xyz="0.0 1.0 0.0"/>
    <origin xyz="0.0 -0.7674999833106995 0.0"/>
  </joint>
  <joint name="axle_rear_right" type="fixed">
    <parent link="rear_axle_link"/>
    <child link="rear_right_wheel_link"/>
    <axis xyz="0.0 1.0 0.0"/>
    <origin xyz="0.0 0.7674999833106995 0.0"/>
  </joint>
  <joint name="jnt_front_left_steer" type="revolute">
    <parent link="front_steer_left_wheel_link"/>
    <child link="front_left_wheel_link"/>
    <axis xyz="0.0 0.0 1.0"/>
    <limit effort="80.0" lower="-0.4886921905584123" upper="0.5235987755982988" velocity="0.05"/>
  </joint>
  <joint name="jnt_front_right_steer" type="revolute">
    <parent link="front_steer_right_wheel_link"/>
    <child link="front_right_wheel_link"/>
    <axis xyz="0.0 0.0 1.0"/>
    <limit effort="80.0" lower="-0.4886921905584123" upper="0.5235987755982988" velocity="0.05"/>
  </joint>
  <joint name="joint_wheel_front_left" type="continuous">
    <parent link="front_left_wheel_link"/>
    <child link="front_left_wheel_link_drive"/>
    <axis xyz="0.0 1.0 0.0"/>
  </joint>
  <joint name="joint_wheel_front_right" type="continuous">
    <parent link="front_right_wheel_link"/>
    <child link="front_right_wheel_link_drive"/>
    <axis xyz="0.0 1.0 0.0"/>
  </joint>
  <joint name="joint_wheel_rear_left" type="continuous">
    <parent link="rear_left_wheel_link"/>
    <child link="rear_left_wheel_link_drive"/>
    <axis xyz="0.0 1.0 0.0"/>
  </joint>
  <joint name="joint_wheel_rear_right" type="continuous">
    <parent link="rear_right_wheel_link"/>
    <child link="rear_right_wheel_link_drive"/>
    <axis xyz="0.0 1.0 0.0"/>
  </joint>
  <joint name="jnt_gnss_kvh" type="fixed">
    <parent link="base_link"/>
    <child link="link_gnss_kvh"/>
    <axis xyz="0.0 0.0 1.0"/>
    <origin xyz="0.1 0.0 -0.1"/>
  </joint>
  <joint name="jnt_laser_front" type="fixed">
    <parent link="base_link"/>
    <child link="link_laser_front"/>
    <axis xyz="0.0 0.0 1.0"/>
    <origin xyz="2.5 0.0 0.0"/>
  </joint>
  <joint name="jnt_vlp16" type="fixed">
    <parent link="base_link"/>
    <child link="link_vlp16"/>
    <axis xyz="0.0 0.0 1.0"/>
    <origin xyz="0.4 0.0 1.2"/>
  </joint>
  <joint name="jnt_camera" type="fixed">
    <parent link="base_link"/>
    <child link="link_camera"/>
    <axis xyz="0.0 0.0 1.0"/>
    <origin xyz="0.9 0.0 1.1"/>
  </joint>
  <joint name="jnt_imu_sensor" type="fixed">
    <parent link="base_link"/>
    <child link="link_imu_sensor"/>
    <axis xyz="0.0 0.0 1.0"/>
    <origin xyz="0.0 0.0 0.0"/>
  </joint>
  <!--GEN START: Transmission definitions-->
  <!--GEN START: Sensor definitions-->
  <gazebo>
    <plugin filename="libhector_gazebo_ros_gps.so" name="gnss_kvh">
      <updateRate>10</updateRate>
      <bodyName>link_gnss_kvh</bodyName>
      <frameId>link_gnss_kvh</frameId>
      <topicName>/gps/fix</topicName>
      <velocityTopicName>/gps/fix_velocity</velocityTopicName>
      <referenceLatitude>47.694</referenceLatitude>
      <referenceLongitude>17.6283</referenceLongitude>
      <referenceAltitude>150.0</referenceAltitude>
      <referenceHeading>90.0</referenceHeading>
    </plugin>
  </gazebo>
  <gazebo reference="link_laser_front">
    <sensor name="laser" type="ray">
      <update_rate>50</update_rate>
      <ray>
        <scan>
          <horizontal>
            <samples>540</samples>
            <resolution>1</resolution>
            <min_angle>-2.0943952</min_angle>
            <max_angle>2.0943952</max_angle>
          </horizontal>
        </scan>
        <range>
          <min>0.4</min>
          <max>30.0</max>
          <resolution>0.1</resolution>
        </range>
      </ray>
      <plugin filename="libgazebo_ros_laser.so" name="laser_laser">
        <topicName>/scan</topicName>
        <frameName>link_laser_front</frameName>
      </plugin>
    </sensor>
  </gazebo>
  <gazebo reference="link_vlp16">
    <sensor name="vlp16" type="gpu_ray">
      <update_rate>10</update_rate>
      <ray>
        <scan>
          <horizontal>
            <samples>2187</samples>
            <resolution>1.0</resolution>
            <min_angle>-3.141592653589793</min_angle>
            <max_angle>3.141592653589793</max_angle>
          </horizontal>
          <vertical>
            <samples>16</samples>
            <resolution>1.0</resolution>
            <min_angle>-0.2617993877991494</min_angle>
            <max_angle>0.2617993877991494</max_angle>
          </vertical>
        </scan>
        <range>
          <min>0.9</min>
          <max>131.0</max>
          <resolution>0.001</resolution>
        </range>
      </ray>
      <plugin filename="libgazebo_ros_velodyne_gpu_laser.so" name="velodyne_vlp16">
        <topicName>/velodyne_points</topicName>
        <frameName>link_vlp16</frameName>
        <min_range>0.9</min_range>
        <max_range>131.0</max_range>
        <gaussianNoise>0.008</gaussianNoise>
      </plugin>
    </sensor>
  </gazebo>
  <gazebo reference="link_camera">
    <sensor name="camera" type="multicamera">
      <update_rate>10</update_rate>
      <camera name="camera_right">
        <pose>-0.07 0 0 0 0 0</pose>
        <horizontal_fov>1.9198621771937625</horizontal_fov>
        <image>
          <width>1920</width>
          <height>1080</height>
          <format>R8G8B8</format>
        </image>
        <clip>
          <near>0.3</near>
          <far>100.0</far>
        </clip>
      </camera>
      <camera name="camera_left">
        <pose>0.07 0 0 0 0 0</pose>
        <horizontal_fov>1.9198621771937625</horizontal_fov>
        <image>
          <width>1920</width>
          <height>1080</height>
          <format>R8G8B8</format>
        </image>
        <clip>
          <near>0.3</near>
          <far>100.0</far>
        </clip>
      </camera>
      <plugin filename="libgazebo_ros_multicamera.so" name="camera_camera_plugin">
        <cameraName>camera</cameraName>
        <imageTopicName>/image_raw</imageTopicName>
        <frameName>link_camera</frameName>
      </plugin>
    </sensor>
  </gazebo>
  <gazebo reference="link_imu_sensor">
    <sensor name="imu_sensor" type="imu">
      <update_rate>45</update_rate>
      <plugin filename="libgazebo_ros_imu_sensor.so" name="imu_imu_sensor_plugin">
        <topicName>/imu</topicName>
        <bodyName>link_imu_sensor</bodyName>
        <updateRateHZ>45</updateRateHZ>
        <frameName>link_imu_sensor</frameName>
      </plugin>
    </sensor>
  </gazebo>
  <!--GEN START: Control plugins-->
  <gazebo>
    <plugin filename="libgazebo_ros_control.so" name="nissanleaf_ros_control">
      <robotNamespace>nissanleaf</robotNamespace>
      <robotSimType>gazebo_ros_control/DefaultRobotHWSim</robotSimType>
    </plugin>
  </gazebo>
  <gazebo>
    <plugin filename="libgazebo_nissan_leaf.so" name="gazebo_nissan_leaf"/>
  </gazebo>
</robot>
